<?xml version="1.0"?>

<robot xmlns:sensor="http://playerstage.sourceforge.net/gazebo/xmlschema/#sensor"
  xmlns:controller="http://playerstage.sourceforge.net/gazebo/xmlschema/#controller"
  xmlns:interface="http://playerstage.sourceforge.net/gazebo/xmlschema/#interface"
  xmlns:xacro="http://ros.org/wiki/xacro"
  name="pioneer3dx">
  
  <xacro:include filename="$(find gazebo_ros_3dx)/defs/sonar_sensor.urdf.xacro"/>
  
  <link name="base_link">
    <!-- The base visual is fine. Just the inertial is questionable.-->
    <visual name="pioneer_geom">
      <origin xyz="-0.045 0 0.148" rpy="0 0 0"/>
      <geometry name="pioneer_geom">
        <mesh filename="package://gazebo_ros_3dx/meshes/p3dx_meshes/chassis.stl"/>
      </geometry>
      <material name="ChassisRed">
        <color rgba="0.851 0.0 0.0 1.0"/>
      </material>
    </visual>
    <collision>
      <origin xyz="-0.045 0 0.148" rpy="0 0 0"/>
      <geometry>
        <!-- this was originally the AT mesh! -->
        <mesh filename="package://gazebo_ros_3dx/meshes/p3dx_meshes/chassis.stl"/>
      </geometry>
    </collision>
  </link>
  
  <gazebo reference="base_link">
    <material value="Gazebo/Red"/>
  </gazebo>
  
  <gazebo>
    <plugin name="lightsensor" filename="liblightsensor_gazebo.so">
      <link name="base_link"/>
      <interval>0.1</interval>
      <pixels>100</pixels>
    </plugin>
  </gazebo>
  
  <link name="dummyinertial">
    <!-- ROS doesn't like a base link with inertia, so farming it out
        to here -->
    <!-- CHECK THESE VALUES. THEY MAY BE COMPLETELY WRONG. -->
    <inertial>
      <mass value="40.0"/>
      <origin xyz="-0.045 0 0.148"/>
      <inertia ixx="0.3338" ixy="0.0" ixz="0.0"
        iyy="0.4783" iyz="0.0"
        izz="0.3338"/>
    </inertial>
  </link>
  
  
  <joint name="dummy_base_joint" type="fixed">
    <origin xyz="0 0 0" rpy="0 0 0"/>
    <parent link="base_link"/>
    <child link="dummyinertial"/>
  </joint>
  
  
  <link name="top_plate">
    <inertial>
      <mass value="0.01"/>	
      <origin xyz="0 0 0"/>
      <inertia ixx="1" ixy="0" ixz="0"
        iyy="1" iyz="0"
        izz="1"/>
    </inertial>
    <visual name="pioneer_geom">
      <origin xyz="0 0 0" rpy="0 0 0"/>
      <geometry name="pioneer_geom">
        <mesh filename="package://gazebo_ros_3dx/meshes/p3dx_meshes/top.stl"/>
      </geometry>
      <material name="TopBlack">
        <color rgba="0.038 0.038 0.038 1.0"/>
      </material>
    </visual>
  </link>
  <gazebo reference="top_plate">
    <material value="Gazebo/Black"/>
  </gazebo>
  
  <joint name="base_top_joint" type="fixed">
    <origin xyz="-0.045 0 0.24" rpy="0 0 0"/>
    <parent link="base_link"/>
    <child link="top_plate"/>
  </joint>
  
  <!-- Swivel -->
  <joint name="base_swivel_joint" type="continuous">
    <origin xyz="-0.185 0 0.055" rpy="0 0 0"/>
    <anchor xyz="0 0 0"/>
    <axis xyz="0 0 1"/>
    <limit effort="100" velocity="100" k_velocity="0" />
    <joint_properties damping="0.0" friction="0.0" />
    <parent link="base_link"/>
    <child link="swivel"/>
  </joint>
  <link name="swivel">
    <inertial>
      <mass value="0.1"/>	
      <origin xyz="0 0 0"/>
      <inertia ixx="0.01" ixy="0" ixz="0"
        iyy="0.01" iyz="0" izz="0.01"/>
    </inertial>
    <visual name="pioneer_geom">
      <origin xyz="0 0 0" rpy="0 0 0"/>
      <geometry name="pioneer_geom">
        <mesh filename="package://gazebo_ros_3dx/meshes/p3dx_meshes/swivel.stl"/>
      </geometry>
      <material name="swivel">
        <color rgba="0.5 0.5 0.5 1"/>
      </material>
    </visual>
    <collision>
      <origin xyz="0 0 0" rpy="0 0 0"/>
      <geometry>
        <box size="0 0 0"/>
      </geometry>
    </collision>
  </link>
  <gazebo reference="swivel">
    <material value="Gazebo/Grey"/>
  </gazebo>
  
  <!-- Center Wheel + Hubcap -->
  
  <joint name="swivel_hubcap_joint" type="continuous">
    <origin xyz="-0.026 0 -0.016" rpy="0 0 0"/>
    <axis xyz="0 1 0"/>
    <anchor xyz="0 0 0"/>
    <limit effort="100" velocity="100" k_velocity="0" />
    <joint_properties damping="0.0" friction="0.0" />
    <parent link="swivel"/>
    <child link="center_wheel"/>
  </joint>
  
  <link name="center_wheel">
    <inertial>
      <mass value="0.1"/>	
      <origin xyz="0 0 0"/>
      <inertia ixx="0.12411765597" ixy="-0.00711733678" ixz="0.0050272983"
        iyy="0.15218160428" iyz="-0.00004273467" izz="0.11763977943"/>
    </inertial>
    <visual name="pioneer_geom">
      <origin xyz="0 0 0" rpy="0 0 0"/>
      <geometry name="pioneer_geom">
        <mesh filename="package://gazebo_ros_3dx/meshes/p3dx_meshes/center_wheel.stl"/>
      </geometry>
      <material name="WheelBlack">
        <color rgba="0.117 0.117 0.117 1"/>
      </material>
    </visual>
    <collision>
      <origin xyz="0 0 0" rpy="${-3.1415927/2.0} 0 0"/>
      <geometry>
        <!--<mesh filename="package://gazebo_ros_3dx/meshes/p3dx_meshes/center_wheel.stl"/>-->
        <cylinder radius="0.0375" length="0.01"/>
      </geometry>
    </collision>
  </link>
  <gazebo reference="center_wheel">
    <material value="Gazebo/Blue"/>
  </gazebo>
  <!--  
      <joint name="center_wheel_joint" type="fixed">
        <origin xyz="-0.0035 0 -0.001" rpy="0 0 0"/>
        <parent link="center_wheel"/>
        <child link="center_hubcap"/>
      </joint>
      -->  
  <!-- Front + Back Sonar -->
  <link name="front_sonar">
    <inertial>
      <mass value="0.0001"/>	
      <origin xyz="0 0 0"/>
      <inertia ixx="1" ixy="0" ixz="0"
        iyy="1" iyz="0" izz="1"/>
    </inertial>
    <visual name="pioneer_geom">
      <origin xyz="0 0 0" rpy="0 0 0"/>
      <geometry name="pioneer_geom">
        <mesh filename="package://gazebo_ros_3dx/meshes/p3dx_meshes/front_sonar.stl"/>
      </geometry>
      <material name="SonarYellow">
        <color rgba="0.715 0.583 0.210 1.0"/>
      </material>
    </visual>
    <collision>
      <origin xyz="0 0 0" rpy="0 0 0"/>
      <geometry>
        <box size="0 0 0"/>
      </geometry>
    </collision>
  </link>
  
  <gazebo reference="front_sonar">
    <material value="Gazebo/Yellow"/>
  </gazebo>
  
  <joint name="base_front_joint" type="fixed">
    <origin xyz="-0.198 0 0.208" rpy="0 0 0"/>
    <parent link="base_link"/>
    <child link="front_sonar"/>
  </joint>
  
  <link name="back_sonar">
    <inertial>
      <mass value="0.0001"/>	
      <origin xyz="0 0 0"/>
      <inertia ixx="1" ixy="0" ixz="0"
        iyy="1" iyz="0" izz="1"/>
    </inertial>
    <visual name="back_sonar_vis">
      <origin xyz="0 0 0" rpy="0 0 0"/>
      <geometry name="pioneer_geom">
        <mesh filename="package://gazebo_ros_3dx/meshes/p3dx_meshes/back_sonar.stl"/>
      </geometry>
      <material name="SonarYellow">
        <color rgba="0.715 0.583 0.210 1.0"/>
      </material>
    </visual>
    <collision>
      <origin xyz="0 0 0" rpy="0 0 0"/>
      <geometry>
        <box size=" 0 0 0"/>
      </geometry>
    </collision>
  </link>
  
  <gazebo reference="back_sonar">
    <material value="Gazebo/Yellow"/>
  </gazebo>
  
  <joint name="base_back_joint" type="fixed">
    <origin xyz="0.109 0 0.209" rpy="0 0 0"/>
    <!-- <origin xyz="0 0 0" rpy="0 0 0"/> -->
    <parent link="base_link"/>
    <child link="back_sonar"/>
  </joint>
  
  <!-- Side wheels (which should be actuated -->
  
  <xacro:macro name="wheel" params="side reflect">
    <link name="${side}_wheel">
      <inertial>
        <mass value="10"/>	
        <origin xyz="0 0 0" rpy="0 1 0"/>
        <inertia 
          ixx="0.165935" 
          ixy="0" 
          ixz="0"
          iyy="0.317959" 
          iyz="0"
          izz="0.165935" 
        />
      </inertial>
      <visual>
        <origin xyz="0 0 0" rpy="0 1 0"/>
        <geometry>
          <mesh filename="package://gazebo_ros_3dx/meshes/p3dx_meshes/${side}_wheel.stl"/>
        </geometry>
        <material name="WheelBlack">
          <color rgba="0.117 0.117 0.117 1"/>
        </material>
      </visual>
      <collision>
        <origin xyz="0 0 0" rpy="${-3.1415927/2.0} 0 0"/>
        <geometry>
          <cylinder radius="0.09" length="0.01"/>
        </geometry>
      </collision>
    </link>
    
    <gazebo reference="${side}_wheel">
      <material value="Gazebo/Black"/>
      <mu1>10</mu1> <!-- rubber friction coeff. -->
      <mu2>10</mu2>
    </gazebo>
    
    <joint name="${side}_wheel_joint" type="continuous">
      <origin xyz="0 ${reflect*0.15} 0.08" rpy="0 0 0"/>
      <axis xyz="0 1 0"/>
      <parent link="base_link"/>
      <child link="${side}_wheel"/>
      <limit effort="100" velocity="100" k_velocity="0" />
      <joint_properties damping="0.0" friction="0.0" />
    </joint>
    
    <transmission name="${side}_wheel_trans">
      <type>transmission_interface/SimpleTransmission</type>
      <actuator name="${side}_wheel_motor">
        <hardwareInterface>VelocityJointInterface</hardwareInterface>
        <mechanicalReduction>${reflect * 624/35 * 80/19}</mechanicalReduction>
      </actuator>
      <joint name="${side}_wheel_joint">
        <hardwareInterface>VelocityJointInterface</hardwareInterface>
      </joint>
    </transmission>
    
  </xacro:macro>
  
  <xacro:wheel side="left" reflect="1"/>
  <xacro:wheel side="right" reflect="-1"/>
  
  <gazebo>
    <plugin name="gazebo_ros_control" filename="libgazebo_ros_control.so">
      <robotNamespace>/p3dx</robotNamespace>
      <robotSimType>gazebo_ros_control/DefaultRobotHWSim</robotSimType>
    </plugin>
  </gazebo>
  
  <!-- test sonar
      <xacro:sonar_sensor name="s1" parent="base_link" 
        ros_topic="s1" update_rate="10" min_range="0.1" max_range="10"
        field_of_view="0.267" ray_count="1">
        <origin xyz="0.2 0 0.22" rpy="0 0 0"/>
      </xacro:sonar_sensor>
      -->  
  
  <xacro:include filename="$(find gazebo_ros_3dx)/defs/camera.urdf.xacro"/>
  
  <xacro:include filename="$(find gazebo_ros_3dx)/defs/sonar_pos.urdf.xacro"/>
  
  <!-- controller 
      
      <gazebo>
        <plugin name="differential_drive_controller" filename="libgazebo_ros_diff_drive.so">
          <updateRate>100.0</updateRate>
          <robotNamespace>/</robotNamespace>
          <leftJoint>left_wheel_joint</leftJoint>
          <rightJoint>right_wheel_joint</rightJoint>
          <wheelSeparation>0.3</wheelSeparation>
          <wheelDiameter>0.1</wheelDiameter>
          <robotBaseFrame>base_link</robotBaseFrame>
          <torque>200</torque>
          <commandTopic>cmd_vel</commandTopic>
          <odometryTopic>odom</odometryTopic>
          <odometryFrame>odom</odometryFrame>
        </plugin>
      </gazebo>
      -->
</robot>
